[2024-12-05T07:06:23.787+0000] {local_task_job_runner.py:120} INFO - ::group::Pre task execution logs
[2024-12-05T07:06:23.946+0000] {taskinstance.py:2076} INFO - Dependencies all met for dep_context=non-requeueable deps ti=<TaskInstance: dbt_elt_process.dbt_run manual__2024-12-05T07:06:22.247738+00:00 [queued]>
[2024-12-05T07:06:23.962+0000] {taskinstance.py:2076} INFO - Dependencies all met for dep_context=requeueable deps ti=<TaskInstance: dbt_elt_process.dbt_run manual__2024-12-05T07:06:22.247738+00:00 [queued]>
[2024-12-05T07:06:23.963+0000] {taskinstance.py:2306} INFO - Starting attempt 1 of 1
[2024-12-05T07:06:23.982+0000] {taskinstance.py:2330} INFO - Executing <Task(BashOperator): dbt_run> on 2024-12-05 07:06:22.247738+00:00
[2024-12-05T07:06:24.014+0000] {logging_mixin.py:188} WARNING - /home/***/.local/lib/python3.12/site-packages/***/task/task_runner/standard_task_runner.py:61 DeprecationWarning: This process (pid=320) is multi-threaded, use of fork() may lead to deadlocks in the child.
[2024-12-05T07:06:24.011+0000] {standard_task_runner.py:90} INFO - Running: ['***', 'tasks', 'run', 'dbt_elt_process', 'dbt_run', 'manual__2024-12-05T07:06:22.247738+00:00', '--job-id', '852', '--raw', '--subdir', 'DAGS_FOLDER/dbt_elt_process.py', '--cfg-path', '/tmp/tmpr492kucf']
[2024-12-05T07:06:24.016+0000] {standard_task_runner.py:63} INFO - Started process 321 to run task
[2024-12-05T07:06:24.017+0000] {standard_task_runner.py:91} INFO - Job 852: Subtask dbt_run
[2024-12-05T07:06:24.130+0000] {task_command.py:426} INFO - Running <TaskInstance: dbt_elt_process.dbt_run manual__2024-12-05T07:06:22.247738+00:00 [running]> on host bbf2723bdd9c
[2024-12-05T07:06:24.240+0000] {taskinstance.py:2648} INFO - Exporting env vars: AIRFLOW_CTX_DAG_OWNER='***' AIRFLOW_CTX_DAG_ID='dbt_elt_process' AIRFLOW_CTX_TASK_ID='dbt_run' AIRFLOW_CTX_EXECUTION_DATE='2024-12-05T07:06:22.247738+00:00' AIRFLOW_CTX_TRY_NUMBER='1' AIRFLOW_CTX_DAG_RUN_ID='manual__2024-12-05T07:06:22.247738+00:00'
[2024-12-05T07:06:24.241+0000] {taskinstance.py:430} INFO - ::endgroup::
[2024-12-05T07:06:24.286+0000] {subprocess.py:63} INFO - Tmp dir root location: /tmp
[2024-12-05T07:06:24.290+0000] {subprocess.py:75} INFO - Running command: ['/usr/bin/bash', '-c', '/home/***/.local/bin/dbt run --profiles-dir /opt/***/dbt_movie/ --project-dir /opt/***/dbt_movie/']
[2024-12-05T07:06:24.309+0000] {subprocess.py:86} INFO - Output:
[2024-12-05T07:06:28.072+0000] {subprocess.py:93} INFO - [0m07:06:28  Running with dbt=1.8.7
[2024-12-05T07:06:28.083+0000] {subprocess.py:93} INFO - [0m07:06:28  Encountered an error:
[2024-12-05T07:06:28.085+0000] {subprocess.py:93} INFO - Runtime Error
[2024-12-05T07:06:28.087+0000] {subprocess.py:93} INFO -   No dbt_project.yml found at expected path /opt/***/dbt_movie/dbt_project.yml
[2024-12-05T07:06:28.091+0000] {subprocess.py:93} INFO -   Verify that each entry within packages.yml (and their transitive dependencies) contains a file named dbt_project.yml
[2024-12-05T07:06:28.094+0000] {subprocess.py:93} INFO - 
[2024-12-05T07:06:29.308+0000] {subprocess.py:97} INFO - Command exited with return code 2
[2024-12-05T07:06:29.323+0000] {taskinstance.py:441} INFO - ::group::Post task execution logs
[2024-12-05T07:06:29.374+0000] {taskinstance.py:2905} ERROR - Task failed with exception
Traceback (most recent call last):
  File "/home/airflow/.local/lib/python3.12/site-packages/airflow/models/taskinstance.py", line 465, in _execute_task
    result = _execute_callable(context=context, **execute_callable_kwargs)
             ^^^^^^^^^^^^^^^^^^^^^^^^^^^^^^^^^^^^^^^^^^^^^^^^^^^^^^^^^^^^^
  File "/home/airflow/.local/lib/python3.12/site-packages/airflow/models/taskinstance.py", line 432, in _execute_callable
    return execute_callable(context=context, **execute_callable_kwargs)
           ^^^^^^^^^^^^^^^^^^^^^^^^^^^^^^^^^^^^^^^^^^^^^^^^^^^^^^^^^^^^
  File "/home/airflow/.local/lib/python3.12/site-packages/airflow/models/baseoperator.py", line 400, in wrapper
    return func(self, *args, **kwargs)
           ^^^^^^^^^^^^^^^^^^^^^^^^^^^
  File "/home/airflow/.local/lib/python3.12/site-packages/airflow/operators/bash.py", line 243, in execute
    raise AirflowException(
airflow.exceptions.AirflowException: Bash command failed. The command returned a non-zero exit code 2.
[2024-12-05T07:06:29.390+0000] {taskinstance.py:1206} INFO - Marking task as FAILED. dag_id=dbt_elt_process, task_id=dbt_run, run_id=manual__2024-12-05T07:06:22.247738+00:00, execution_date=20241205T070622, start_date=20241205T070623, end_date=20241205T070629
[2024-12-05T07:06:29.426+0000] {standard_task_runner.py:110} ERROR - Failed to execute job 852 for task dbt_run (Bash command failed. The command returned a non-zero exit code 2.; 321)
[2024-12-05T07:06:29.444+0000] {local_task_job_runner.py:240} INFO - Task exited with return code 1
[2024-12-05T07:06:29.483+0000] {taskinstance.py:3498} INFO - 0 downstream tasks scheduled from follow-on schedule check
[2024-12-05T07:06:29.487+0000] {local_task_job_runner.py:222} INFO - ::endgroup::
